Workbook
Name AAA: [1]!Table23[#Data]
Name bbb: ROW(#REF!)
Name bbb: ROW(#REF!)
Name Beg_Bal: #REF!
Name Beg_Bal: '[2]Loan Amortization Schedule'!$C$18:$C$497
Name bet: DATE(YEAR([3]!Loan_Start),MONTH([3]!Loan_Start)+Payment_Number,DAY([3]!Loan_Start))
Name bet: DATE(YEAR(Loan_Start),MONTH(Loan_Start)+Payment_Number,DAY(Loan_Start))
Name BEthelehem: #REF!
Name BEthelehem: #REF!
Name beti: #REF!
Name beti: #REF!
Name bnvc: #REF!
Name bnvc: #REF!
Name bvcb: #REF!
Name bvcb: #REF!
Name cbcv: #REF!
Name cbcv: #REF!
Name Cum_Int: #REF!
Name Cum_Int: #REF!
Name cvb: #REF!
Name cvb: #REF!
Name cvbcv: #REF!
Name cvbcv: #REF!
Name cvbvc: #REF!
Name cvbvc: #REF!
Name Data: #REF!
Name Data: #REF!
Name dgfdgc: OFFSET('All Ticket'!xbx,0,0,'All Ticket'!vcb)
Name dgfdgc: OFFSET(xbx,0,0,vcb)
Name dinaras: #REF!
Name dinaras: #REF!
Name Employee: [1]!Table23[#Data]
Name End_Bal: '[2]Loan Amortization Schedule'!$I$18:$I$497
Name Extra_Pay: #REF!
Name Extra_Pay: '[2]Loan Amortization Schedule'!$E$18:$E$497
Name f: DATE(YEAR('All Ticket'!vbvccvb),MONTH('All Ticket'!vbvccvb)+Payment_Number,DAY('All Ticket'!vbvccvb))
Name f: DATE(YEAR(vbvccvb),MONTH(vbvccvb)+Payment_Number,DAY(vbvccvb))
Name fg: #REF!
Name fg: #REF!
Name Full_Print: '[2]Loan Amortization Schedule'!$A$1:$J$497
Name g: #REF!
Name g: #REF!
Name gg: #REF!
Name gg: #REF!
Name Grade: [1]!Table19[#Data]
Name h: #REF!
Name h: #REF!
Name Header_Row: ROW('[2]Loan Amortization Schedule'!$17:$17)
Name Int: #REF!
Name Int: '[2]Loan Amortization Schedule'!$H$18:$H$497
Name Interest_Rate: '[2]Loan Amortization Schedule'!$D$6
Name j: MATCH(0.01,'All Ticket'!fg,-1)+1
Name j: MATCH(0.01,fg,-1)+1
Name kirubel: #REF!
Name kirubel: #REF!
Name kkk: #REF!
Name kkk: #REF!
Name Last_Row: IF('All Ticket'!Values_Entered,[3]!Header_Row+'All Ticket'!Number_of_Payments,[3]!Header_Row)
Name Last_Row: IF(Values_Entered,Header_Row+Number_of_Payments,Header_Row)
Name Loan_Amount: '[2]Loan Amortization Schedule'!$D$5

Sheet All Ticket
F3: Date | G3: =TODAY()+1 -> 46282
E5: ATM Rent Schedule Ticket
B7: DEBIT
B8: Branch Code | C8: Branch Name | D8: GL Number | E8: Description | F8: Amount | G8: In Respect Of
B9: 108 | C9: =VLOOKUP(B9,'All Ticket'!$D$219:$E$386,2,0) -> #N/A | D9: 502149 | E9: =VLOOKUP(D9,'All Ticket'!$F$219:$G$743,2,0) -> #N/A | F9: ='[6]August 2026 Schedule'!X240 -> 2341496.7 | G9: ATM Space Rent for the Month of August 2026.
B10: Debit Total | F10: =SUM(F9:F9) -> 2341496.7
B12: CREDIT
B13: Branch Code | C13: Branch Name | D13: GL Number | E13: Description | F13: Amount | G13: In Respect Of
B14: 000 | C14: =VLOOKUP(B14,'All Ticket'!$D$219:$E$386,2,0) -> #N/A | D14: 208130 | E14: =VLOOKUP(D14,'All Ticket'!$F$219:$G$743,2,0) -> #N/A | F14: ='[6]August 2026 Schedule'!Z240 -> 489955.32 | G14: Amount held under A/P Miscellaneous for different ATM space rent for the month of August ,2026.
B15: 000 | C15: =VLOOKUP(B15,'All Ticket'!$D$219:$E$386,2,0) -> #N/A | D15: 104401 | E15: =VLOOKUP(D15,'All Ticket'!$F$219:$G$743,2,0) -> #N/A | F15: ='[6]August 2026 Schedule'!X240-'[6]August 2026 Schedule'!Z240 -> 1851541.3 | G15: =G9 -> ATM Space Rent for the Month of August 2026.
B16: Credit Total | F16: =SUM(F14:F15) -> 2341496.7
D17: =F10-F16 -> 0
B19: IN RESPECT OF:
D20: =G9 -> ATM Space Rent for the Month of August 2026.
B21: AMOUNT IN WORDS:
D22: BIRR
D23: =[7]!spellNumber(F16) -> #NAME?
F25: ………………………………………………………………………………………………………………………………
G26: Authorized Signature
F29: Date | G29: =TODAY()+1 -> 46282
E31: Office Rent Ticket (City Branches )
B33: DEBIT
B34: Branch Code | C34: Branch Name | D34: GL Number | E34: Description | F34: Amount | G34: In Respect Of
B35: 103 | C35: =VLOOKUP(B35,'All Ticket'!$D$219:$E$403,2,0) -> #N/A | D35: 502149 | E35: =VLOOKUP(D35,'All Ticket'!$F$219:$G$743,2,0) -> #N/A | F35: 524129.53 | G35: Office rent and stamp duty expense of Kazanchis Branch for the month of August ,2026.
B36: 106 | C36: =VLOOKUP(B36,'All Ticket'!$D$219:$E$403,2,0) -> #N/A | D36: 502149 | E36: =VLOOKUP(D36,'All Ticket'!$F$219:$G$743,2,0) -> #N/A | F36: 197633.25 | G36: Office rent and stamp duty expense of Mexico Branch for the month of August ,2026.
B57: DEBIT TOTAL | F57: amount of summation
B121: CREDIT
B122: Branch Code | C122: Branch Name | D122: GL Number | E122: Description | F122: Amount | G122: In Respect Of
B123: 000 | C123: =VLOOKUP(B123,'All Ticket'!$D$219:$E$386,2,0) -> #N/A | D123: 104401 | E123: =VLOOKUP(D123,'All Ticket'!$F$219:$G$743,2,0) -> #N/A | F123: ='[6]August 2026 Schedule'!X442-'[6]August 2026 Schedule'!Z442 -> 14892263 | G123: Office rent and stamp duty expense of City Branches for the month of August ,2026.
B124: 000 | C124: =VLOOKUP(B124,'All Ticket'!$D$219:$E$386,2,0) -> #N/A | D124: 208130 | E124: =VLOOKUP(D124,'All Ticket'!$F$219:$G$743,2,0) -> #N/A | F124: ='[6]August 2026 Schedule'!Z442 -> 178770 | G124: Amount held under A/P Miscellaneous for different Office and ATM space rent for the month of August ,2026.
B125: Credit Total | F125: =SUM(F123:F124) -> 15071033
D126: =F119-F125 -> -15071033
B128: IN RESPECT OF:
D129: =G123 -> Office rent and stamp duty expense of City Branches for the month of August ,2026.
B130: AMOUNT IN WORDS:
D131: BIRR
D132: =[7]!spellNumber(F125) -> #NAME?
F134: ………………………………………………………………………………………………………………………………
G135: Authorized Signature
F138: Date | G138: =TODAY()+1 -> 46282
...

Sheet Report
B2: Zemen Bank S.C
B3: Monthly Amortization Report for for ATM
B4: For the month of September
B5: S/No | C5: Box File No | D5: Category of Rent | E5: Branch Name | F5: Branch Code | G5: Owner Name | H5: Contract Start | I5: Contract End | J5: Total No. of Years | K5: Payment Paid to Date | L5: Year with Fraction | M5: Meter Square | N5: Price/m² Before VAT | O5: VAT Rate | P5: Price/m² After VAT | Q5: Monthly Rent with VAT | R5: Total Annual Rent | S5: Utility / Service Charge | T5: Full Payment | U5: Total Payment Paid | V5: Remaining Payment | W5: Outstanding Balance (Prev) | X5: Rent Expense | Y5: Due | Z5: Rent Expense − Due | AA5: Reent Expense As Of | AB5: Due Difference As Of | AC5: Prepaid | AD5: Additional Expense | AE5: Day | AF5: Outstanding End
X8: 500000
Y10: 10000
C19: Total | D19: =SUM(D6:D18) -> 0 | E19: =SUM(E6:E18) -> 0 | F19: =SUM(F6:F18) -> 0 | G19: =SUM(G6:G18) -> 0 | H19: =SUM(H6:H18) -> 0 | I19: =SUM(I6:I18) -> 0 | J19: =SUM(J6:J18) -> 0 | K19: =SUM(K6:K18) -> 0 | ... AF19: =SUM(AF6:AF18) -> 0
D22: Prepared By________________________________________
N24: Checked By________________________________________
E26: Possible Entry for the Month of September
E27: Describtion | F27: Dr | G27: Cr
E28: Expense | F28: =X19 -> 500000
E29: Payable | G29: =Y19 -> 10000
E30: Prepaid | G30: =X19-Y19 -> 490000
E31: Total | F31: =SUM(F28:F30) -> 500000 | G31: =SUM(G28:G30) -> 500000
